2020-02-06 20:43:44,256 - PIL.PngImagePlugin - DEBUG - STREAM b'IHDR' 16 13
2020-02-06 20:43:44,256 - PIL.PngImagePlugin - DEBUG - STREAM b'sBIT' 41 3
2020-02-06 20:43:44,256 - PIL.PngImagePlugin - DEBUG - b'sBIT' 41 3 (unknown)
2020-02-06 20:43:44,256 - PIL.PngImagePlugin - DEBUG - STREAM b'tEXt' 56 16
2020-02-06 20:43:44,256 - PIL.PngImagePlugin - DEBUG - STREAM b'IDAT' 84 8192
2020-02-06 20:45:02,649 - root - INFO - Γραμμή 733: ---------------ΛΟΓΟΣ BACKUP --->>> ΕΠΕΞΕΡΓΑΣΙΑ ΔΕΔΟΜΕΝΩΝ ------------------------- 
2020-02-06 20:45:02,649 - root - INFO - 

2020-02-06 20:45:02,680 - root - INFO - ************************************************************
2020-02-06 20:45:02,680 - root - INFO - 

2020-02-06 20:45:02,680 - root - INFO - **************************************************
2020-02-06 20:45:02,680 - root - INFO -  
2020-02-06 20:45:02,680 - root - INFO - Το προΐον ενημερώθηκε με επιτυχία
2020-02-06 20:45:02,680 - root - INFO -  
2020-02-06 20:45:02,680 - root - INFO - **************************************************
2020-02-06 20:45:02,680 - root - INFO - 

2020-02-06 20:45:02,680 - root - INFO - ************************************************************
2020-02-06 20:45:02,680 - root - INFO - 

2020-02-06 20:45:02,680 - root - INFO - Γραμμη 580 Παλιά δεδομένα στον πίνακα ==> ΧΧΧ
2020-02-06 20:45:02,680 - root - INFO -  
2020-02-06 20:45:02,680 - root - INFO - 

2020-02-06 20:45:02,680 - root - INFO -  
2020-02-06 20:45:02,680 - root - INFO - ['ΚΩΔΙΚΟΣ', 'ΗΜΕΡΩΜΗΝΙΑ', 'ΠΕΡΙΓΡΑΦΗ', 'ΑΠΟΤΕΛΕΣΜΑ', 'ΠΑΡΑΤΗΡΗΣΕΙΣ']
2020-02-06 20:45:02,680 - root - INFO -  
2020-02-06 20:45:02,680 - root - INFO - 

2020-02-06 20:45:02,680 - root - INFO -  
2020-02-06 20:45:02,680 - root - INFO - ['', '06/02/2020', 'KONICA MINOLTA bizhub 36 35 ADF PICKUP ROLLLER ORIGINAL', '', 'dannys']
2020-02-06 20:45:02,680 - root - INFO - 

2020-02-06 20:45:02,680 - root - INFO - Γραμμη 581 Νέα δεδομένα στον πίνακα ==>ΧΧΧ
2020-02-06 20:45:02,680 - root - INFO -  
2020-02-06 20:45:02,680 - root - INFO - 

2020-02-06 20:45:02,680 - root - INFO -  
2020-02-06 20:45:02,680 - root - INFO - ['ΚΩΔΙΚΟΣ', 'ΗΜΕΡΩΜΗΝΙΑ', 'ΠΕΡΙΓΡΑΦΗ', 'ΑΠΟΤΕΛΕΣΜΑ', 'ΠΑΡΑΤΗΡΗΣΕΙΣ']
2020-02-06 20:45:02,680 - root - INFO -  
2020-02-06 20:45:02,680 - root - INFO - 

2020-02-06 20:45:02,680 - root - INFO -  
2020-02-06 20:45:02,680 - root - INFO - ['', '06/02/2020', 'KONICA MINOLTA bizhub 36 35 ADF PICKUP ROLLLER ORIGINAL 63.0017.5494', '', 'COSTUMERS']
2020-02-06 20:45:02,680 - root - INFO - 

2020-02-06 20:45:11,246 - PIL.PngImagePlugin - DEBUG - STREAM b'IHDR' 16 13
2020-02-06 20:45:11,246 - PIL.PngImagePlugin - DEBUG - STREAM b'sBIT' 41 3
2020-02-06 20:45:11,246 - PIL.PngImagePlugin - DEBUG - b'sBIT' 41 3 (unknown)
2020-02-06 20:45:11,246 - PIL.PngImagePlugin - DEBUG - STREAM b'tEXt' 56 16
2020-02-06 20:45:11,246 - PIL.PngImagePlugin - DEBUG - STREAM b'IDAT' 84 8192
2020-02-06 20:45:15,785 - root - ERROR - Exception in Tkinter callback
2020-02-06 20:45:15,785 - root - ERROR - 

2020-02-06 20:45:15,801 - root - ERROR - Traceback (most recent call last):

2020-02-06 20:45:15,801 - root - ERROR - 
2020-02-06 20:45:15,801 - root - ERROR -   File "image_viewer.py", line 250, in get_size_of_files

2020-02-06 20:45:15,801 - root - ERROR - 
2020-02-06 20:45:15,801 - root - ERROR - IndexError: list index out of range

2020-02-06 20:45:15,801 - root - ERROR - 
2020-02-06 20:45:15,801 - root - ERROR - 
During handling of the above exception, another exception occurred:


2020-02-06 20:45:15,801 - root - ERROR - 
2020-02-06 20:45:15,801 - root - ERROR - Traceback (most recent call last):

2020-02-06 20:45:15,801 - root - ERROR - 
2020-02-06 20:45:15,801 - root - ERROR -   File "tkinter\__init__.py", line 1883, in __call__

2020-02-06 20:45:15,801 - root - ERROR - 
2020-02-06 20:45:15,801 - root - ERROR -   File "Αποθηκη.pyw", line 1289, in show_files

2020-02-06 20:45:15,801 - root - ERROR - 
2020-02-06 20:45:15,801 - root - ERROR -   File "image_viewer.py", line 78, in create_Toplevel1

2020-02-06 20:45:15,801 - root - ERROR - 
2020-02-06 20:45:15,801 - root - ERROR -   File "image_viewer.py", line 241, in __init__

2020-02-06 20:45:15,801 - root - ERROR - 
2020-02-06 20:45:15,801 - root - ERROR -   File "image_viewer.py", line 252, in get_size_of_files

2020-02-06 20:45:15,801 - root - ERROR - 
2020-02-06 20:45:15,801 - root - ERROR - IndexError: list index out of range

2020-02-06 20:45:15,801 - root - ERROR - 
2020-02-06 20:45:22,743 - root - ERROR - Exception in Tkinter callback
2020-02-06 20:45:22,743 - root - ERROR - 

2020-02-06 20:45:22,743 - root - ERROR - Traceback (most recent call last):

2020-02-06 20:45:22,743 - root - ERROR - 
2020-02-06 20:45:22,743 - root - ERROR -   File "image_viewer.py", line 250, in get_size_of_files

2020-02-06 20:45:22,743 - root - ERROR - 
2020-02-06 20:45:22,743 - root - ERROR - IndexError: list index out of range

2020-02-06 20:45:22,743 - root - ERROR - 
2020-02-06 20:45:22,743 - root - ERROR - 
During handling of the above exception, another exception occurred:


2020-02-06 20:45:22,743 - root - ERROR - 
2020-02-06 20:45:22,743 - root - ERROR - Traceback (most recent call last):

2020-02-06 20:45:22,743 - root - ERROR - 
2020-02-06 20:45:22,743 - root - ERROR -   File "tkinter\__init__.py", line 1883, in __call__

2020-02-06 20:45:22,743 - root - ERROR - 
2020-02-06 20:45:22,743 - root - ERROR -   File "Αποθηκη.pyw", line 1289, in show_files

2020-02-06 20:45:22,743 - root - ERROR - 
2020-02-06 20:45:22,743 - root - ERROR -   File "image_viewer.py", line 78, in create_Toplevel1

2020-02-06 20:45:22,743 - root - ERROR - 
2020-02-06 20:45:22,743 - root - ERROR -   File "image_viewer.py", line 241, in __init__

2020-02-06 20:45:22,743 - root - ERROR - 
2020-02-06 20:45:22,743 - root - ERROR -   File "image_viewer.py", line 252, in get_size_of_files

2020-02-06 20:45:22,743 - root - ERROR - 
2020-02-06 20:45:22,743 - root - ERROR - IndexError: list index out of range

2020-02-06 20:45:22,743 - root - ERROR - 
2020-02-06 20:47:53,933 - root - ERROR - Exception in Tkinter callback
2020-02-06 20:47:53,933 - root - ERROR - 

2020-02-06 20:47:53,933 - root - ERROR - Traceback (most recent call last):

2020-02-06 20:47:53,933 - root - ERROR - 
2020-02-06 20:47:53,933 - root - ERROR -   File "image_viewer.py", line 250, in get_size_of_files

2020-02-06 20:47:53,933 - root - ERROR - 
2020-02-06 20:47:53,933 - root - ERROR - IndexError: list index out of range

2020-02-06 20:47:53,933 - root - ERROR - 
2020-02-06 20:47:53,933 - root - ERROR - 
During handling of the above exception, another exception occurred:


2020-02-06 20:47:53,933 - root - ERROR - 
2020-02-06 20:47:53,933 - root - ERROR - Traceback (most recent call last):

2020-02-06 20:47:53,933 - root - ERROR - 
2020-02-06 20:47:53,933 - root - ERROR -   File "tkinter\__init__.py", line 1883, in __call__

2020-02-06 20:47:53,933 - root - ERROR - 
2020-02-06 20:47:53,933 - root - ERROR -   File "Αποθηκη.pyw", line 1289, in show_files

2020-02-06 20:47:53,933 - root - ERROR - 
2020-02-06 20:47:53,933 - root - ERROR -   File "image_viewer.py", line 78, in create_Toplevel1

2020-02-06 20:47:53,933 - root - ERROR - 
2020-02-06 20:47:53,933 - root - ERROR -   File "image_viewer.py", line 241, in __init__

2020-02-06 20:47:53,933 - root - ERROR - 
2020-02-06 20:47:53,933 - root - ERROR -   File "image_viewer.py", line 252, in get_size_of_files

2020-02-06 20:47:53,933 - root - ERROR - 
2020-02-06 20:47:53,933 - root - ERROR - IndexError: list index out of range

2020-02-06 20:47:53,933 - root - ERROR - 
2020-02-06 20:48:07,521 - root - ERROR - Exception in Tkinter callback
2020-02-06 20:48:07,521 - root - ERROR - 

2020-02-06 20:48:07,521 - root - ERROR - Traceback (most recent call last):

2020-02-06 20:48:07,521 - root - ERROR - 
2020-02-06 20:48:07,521 - root - ERROR -   File "image_viewer.py", line 250, in get_size_of_files

2020-02-06 20:48:07,521 - root - ERROR - 
2020-02-06 20:48:07,521 - root - ERROR - IndexError: list index out of range

2020-02-06 20:48:07,521 - root - ERROR - 
2020-02-06 20:48:07,521 - root - ERROR - 
During handling of the above exception, another exception occurred:


2020-02-06 20:48:07,521 - root - ERROR - 
2020-02-06 20:48:07,521 - root - ERROR - Traceback (most recent call last):

2020-02-06 20:48:07,521 - root - ERROR - 
2020-02-06 20:48:07,521 - root - ERROR -   File "tkinter\__init__.py", line 1883, in __call__

2020-02-06 20:48:07,521 - root - ERROR - 
2020-02-06 20:48:07,521 - root - ERROR -   File "Αποθηκη.pyw", line 1289, in show_files

2020-02-06 20:48:07,521 - root - ERROR - 
2020-02-06 20:48:07,521 - root - ERROR -   File "image_viewer.py", line 78, in create_Toplevel1

2020-02-06 20:48:07,521 - root - ERROR - 
2020-02-06 20:48:07,521 - root - ERROR -   File "image_viewer.py", line 241, in __init__

2020-02-06 20:48:07,521 - root - ERROR - 
2020-02-06 20:48:07,521 - root - ERROR -   File "image_viewer.py", line 252, in get_size_of_files

2020-02-06 20:48:07,521 - root - ERROR - 
2020-02-06 20:48:07,521 - root - ERROR - IndexError: list index out of range

2020-02-06 20:48:07,521 - root - ERROR - 
2020-02-06 20:48:10,485 - root - ERROR - Exception in Tkinter callback
2020-02-06 20:48:10,485 - root - ERROR - 

2020-02-06 20:48:10,485 - root - ERROR - Traceback (most recent call last):

2020-02-06 20:48:10,485 - root - ERROR - 
2020-02-06 20:48:10,485 - root - ERROR -   File "image_viewer.py", line 250, in get_size_of_files

2020-02-06 20:48:10,485 - root - ERROR - 
2020-02-06 20:48:10,485 - root - ERROR - IndexError: list index out of range

2020-02-06 20:48:10,485 - root - ERROR - 
2020-02-06 20:48:10,485 - root - ERROR - 
During handling of the above exception, another exception occurred:


2020-02-06 20:48:10,485 - root - ERROR - 
2020-02-06 20:48:10,485 - root - ERROR - Traceback (most recent call last):

2020-02-06 20:48:10,485 - root - ERROR - 
2020-02-06 20:48:10,485 - root - ERROR -   File "tkinter\__init__.py", line 1883, in __call__

2020-02-06 20:48:10,485 - root - ERROR - 
2020-02-06 20:48:10,485 - root - ERROR -   File "Αποθηκη.pyw", line 1289, in show_files

2020-02-06 20:48:10,485 - root - ERROR - 
2020-02-06 20:48:10,485 - root - ERROR -   File "image_viewer.py", line 78, in create_Toplevel1

2020-02-06 20:48:10,485 - root - ERROR - 
2020-02-06 20:48:10,485 - root - ERROR -   File "image_viewer.py", line 241, in __init__

2020-02-06 20:48:10,485 - root - ERROR - 
2020-02-06 20:48:10,485 - root - ERROR -   File "image_viewer.py", line 252, in get_size_of_files

2020-02-06 20:48:10,485 - root - ERROR - 
2020-02-06 20:48:10,485 - root - ERROR - IndexError: list index out of range

2020-02-06 20:48:10,500 - root - ERROR - 
